Workbook
Name Slicer_Branch: #N/A
Name Slicer_Customer_type: #N/A
Name Slicer_Payment: #N/A

Sheet Supermarket Sales 
A1: Date | B1: Branch | C1: Customer type | D1: Gender | E1: Product line | F1: Unit price | G1: Quantity | H1: Payment | I1: Rating | J1: Total sales | K1: Tax amount | L1: Rating Category | M1: =AVERAGE(I2:I5054) -> 6.8840293
A2: 45292 | B2: Brooklyn | C2: Member | D2: Female | E2: Food & Beverages | F2: 84.63 | G2: 10 | H2: Credit card | I2: 9 | J2: =F2*G2 -> 846.3 | K2: =J2*5% -> 42.315 | L2: {=_xlfn.IFS(I2>=9,"Good",I2>=6,"Average",I2<6,"Poor")} -> Good
A3: 45292 | B3: Queens | C3: Normal | D3: Female | E3: Electronics | F3: 63.22 | G3: 2 | H3: Cash | I3: 8.5 | J3: =F3*G3 -> 126.44 | K3: =J3*5% -> 6.322 | L3: {=_xlfn.IFS(I3>=9,"Good",I3>=6,"Average",I3<6,"Poor")} -> Average | N3: TAX
A4: 45292 | B4: Brooklyn | C4: Normal | D4: Female | E4: Electronics | F4: 74.71 | G4: 6 | H4: Cash | I4: 6.7 | J4: =F4*G4 -> 448.26 | K4: =J4*5% -> 22.413 | L4: {=_xlfn.IFS(I4>=9,"Good",I4>=6,"Average",I4<6,"Poor")} -> Average | N4: 0.05
A5: 45292 | B5: Queens | C5: Member | D5: Female | E5: Sports & Travel | F5: 36.98 | G5: 10 | H5: Credit card | I5: 7 | J5: =F5*G5 -> 369.8 | K5: =J5*5% -> 18.49 | L5: {=_xlfn.IFS(I5>=9,"Good",I5>=6,"Average",I5<6,"Poor")} -> Average
A6: 45292 | B6: Manhattan | C6: Member | D6: Female | E6: Sports & Travel | F6: 27.04 | G6: 4 | H6: Ewallet | I6: 6.9 | J6: =F6*G6 -> 108.16 | K6: =J6*5% -> 5.408 | L6: {=_xlfn.IFS(I6>=9,"Good",I6>=6,"Average",I6<6,"Poor")} -> Average
A7: 45292 | B7: Manhattan | C7: Normal | D7: Female | E7: Fashion & Accs | F7: 65.74 | G7: 9 | H7: Cash | I7: 7.7 | J7: =F7*G7 -> 591.66 | K7: =J7*5% -> 29.583 | L7: {=_xlfn.IFS(I7>=9,"Good",I7>=6,"Average",I7<6,"Poor")} -> Average
A8: 45292 | B8: Manhattan | C8: Member | D8: Male | E8: Home & Lifestyle | F8: 47.59 | G8: 8 | H8: Cash | I8: 5.7 | J8: =F8*G8 -> 380.72 | K8: =J8*5% -> 19.036 | L8: {=_xlfn.IFS(I8>=9,"Good",I8>=6,"Average",I8<6,"Poor")} -> Poor
A9: 45292 | B9: Manhattan | C9: Normal | D9: Male | E9: Sports & Travel | F9: 72.61 | G9: 6 | H9: Credit card | I9: 6.9 | J9: =F9*G9 -> 435.66 | K9: =J9*5% -> 21.783 | L9: {=_xlfn.IFS(I9>=9,"Good",I9>=6,"Average",I9<6,"Poor")} -> Average
A10: 45292 | B10: Queens | C10: Normal | D10: Male | E10: Health & Beauty | F10: 62.87 | G10: 2 | H10: Cash | I10: 5 | J10: =F10*G10 -> 125.74 | K10: =J10*5% -> 6.287 | L10: {=_xlfn.IFS(I10>=9,"Good",I10>=6,"Average",I10<6,"Poor")} -> Poor
A11: 45292 | B11: Brooklyn | C11: Normal | D11: Male | E11: Food & Beverages | F11: 21.12 | G11: 8 | H11: Cash | I11: 6.3 | J11: =F11*G11 -> 168.96 | K11: =J11*5% -> 8.448 | L11: {=_xlfn.IFS(I11>=9,"Good",I11>=6,"Average",I11<6,"Poor")} -> Average
A12: 45292 | B12: Queens | C12: Member | D12: Female | E12: Sports & Travel | F12: 29.22 | G12: 6 | H12: Ewallet | I12: 5 | J12: =F12*G12 -> 175.32 | K12: =J12*5% -> 8.766 | L12: {=_xlfn.IFS(I12>=9,"Good",I12>=6,"Average",I12<6,"Poor")} -> Poor
A13: 45292 | B13: Manhattan | C13: Member | D13: Female | E13: Electronics | F13: 74.22 | G13: 10 | H13: Credit card | I13: 4.3 | J13: =F13*G13 -> 742.2 | K13: =J13*5% -> 37.11 | L13: {=_xlfn.IFS(I13>=9,"Good",I13>=6,"Average",I13<6,"Poor")} -> Poor
A14: 45323 | B14: Manhattan | C14: Normal | D14: Male | E14: Sports & Travel | F14: 42.47 | G14: 1 | H14: Cash | I14: 5.7 | J14: =F14*G14 -> 42.47 | K14: =J14*5% -> 2.1235 | L14: {=_xlfn.IFS(I14>=9,"Good",I14>=6,"Average",I14<6,"Poor")} -> Poor
A15: 45323 | B15: Brooklyn | C15: Member | D15: Male | E15: Fashion & Accs | F15: 40.61 | G15: 9 | H15: Cash | I15: 7 | J15: =F15*G15 -> 365.49 | K15: =J15*5% -> 18.2745 | L15: {=_xlfn.IFS(I15>=9,"Good",I15>=6,"Average",I15<6,"Poor")} -> Average
A16: 45323 | B16: Brooklyn | C16: Normal | D16: Male | E16: Sports & Travel | F16: 44.63 | G16: 6 | H16: Credit card | I16: 5.1 | J16: =F16*G16 -> 267.78 | K16: =J16*5% -> 13.389 | L16: {=_xlfn.IFS(I16>=9,"Good",I16>=6,"Average",I16<6,"Poor")} -> Poor
... A119: 45627 | B119: Brooklyn | C119: Normal | D119: Female | E119: Home & Lifestyle | F119: 51.07 | G119: 7 | H119: Cash | I119: 7 | J119: =F119*G119 -> 357.49 | K119: =J119*5% -> 17.8745 | L119: {=_xlfn.IFS(I119>=9,"Good",I119>=6,"Average",I119<6,"Poor")} -> Average
A120: 1/13/2024 | B120: Brooklyn | C120: Member | D120: Male | E120: Sports & Travel | F120: 72.6 | G120: 6 | H120: Cash | I120: 6.9 | J120: =F120*G120 -> 435.6 | K120: =J120*5% -> 21.78 | L120: {=_xlfn.IFS(I120>=9,"Good",I120>=6,"Average",I120<6,"Poor")} -> Average
A121: 1/13/2024 | B121: Manhattan | C121: Member | D121: Male | E121: Home & Lifestyle | F121: 81.01 | G121: 3 | H121: Credit card | I121: 9.3 | J121: =F121*G121 -> 243.03 | K121: =J121*5% -> 12.1515 | L121: {=_xlfn.IFS(I121>=9,"Good",I121>=6,"Average",I121<6,"Poor")} -> Good
A122: 1/13/2024 | B122: Queens | C122: Member | D122: Female | E122: Fashion & Accs | F122: 74.29 | G122: 1 | H122: Cash | I122: 5 | J122: =F122*G122 -> 74.29 | K122: =J122*5% -> 3.7145 | L122: {=_xlfn.IFS(I122>=9,"Good",I122>=6,"Average",I122<6,"Poor")} -> Poor
A123: 1/13/2024 | B123: Manhattan | C123: Normal | D123: Female | E123: Electronics | F123: 23.46 | G123: 6 | H123: Ewallet | I123: 6.4 | J123: =F123*G123 -> 140.76 | K123: =J123*5% -> 7.038 | L123: {=_xlfn.IFS(I123>=9,"Good",I123>=6,"Average",I123<6,"Poor")} -> Average
A124: 1/13/2024 | B124: Manhattan | C124: Member | D124: Female | E124: Health & Beauty | F124: 39.62 | G124: 9 | H124: Credit card | I124: 6.8 | J124: =F124*G124 -> 356.58 | K124: =J124*5% -> 17.829 | L124: {=_xlfn.IFS(I124>=9,"Good",I124>=6,"Average",I124<6,"Poor")} -> Average
A125: 1/13/2024 | B125: Queens | C125: Member | D125: Female | E125: Food & Beverages | F125: 21.04 | G125: 4 | H125: Cash | I125: 7.6 | J125: =F125*G125 -> 84.16 | K125: =J125*5% -> 4.208 | L125: {=_xlfn.IFS(I125>=9,"Good",I125>=6,"Average",I125<6,"Poor")} -> Average
A126: 1/13/2024 | B126: Brooklyn | C126: Member | D126: Male | E126: Fashion & Accs | F126: 59.86 | G126: 2 | H126: Ewallet | I126: 6.7 | J126: =F126*G126 -> 119.72 | K126: =J126*5% -> 5.986 | L126: {=_xlfn.IFS(I126>=9,"Good",I126>=6,"Average",I126<6,"Poor")} -> Average
A127: 1/13/2024 | B127: Brooklyn | C127: Normal | D127: Male | E127: Food & Beverages | F127: 72.39 | G127: 2 | H127: Credit card | I127: 8.1 | J127: =F127*G127 -> 144.78 | K127: =J127*5% -> 7.239 | L127: {=_xlfn.IFS(I127>=9,"Good",I127>=6,"Average",I127<6,"Poor")} -> Average
A128: 1/13/2024 | B128: Manhattan | C128: Normal | D128: Male | E128: Sports & Travel | F128: 45.58 | G128: 7 | H128: Cash | I128: 5 | J128: =F128*G128 -> 319.06 | K128: =J128*5% -> 15.953 | L128: {=_xlfn.IFS(I128>=9,"Good",I128>=6,"Average",I128<6,"Poor")} -> Poor
A129: 1/13/2024 | B129: Queens | C129: Normal | D129: Female | E129: Electronics | F129: 41.65 | G129: 10 | H129: Credit card | I129: 5.4 | J129: =F129*G129 -> 416.5 | K129: =J129*5% -> 20.825 | L129: {=_xlfn.IFS(I129>=9,"Good",I129>=6,"Average",I129<6,"Poor")} -> Poor
A130: 1/14/2024 | B130: Queens | C130: Member | D130: Male | E130: Health & Beauty | F130: 60.47 | G130: 3 | H130: Credit card | I130: 5.6 | J130: =F130*G130 -> 181.41 | K130: =J130*5% -> 9.0705 | L130: {=_xlfn.IFS(I130>=9,"Good",I130>=6,"Average",I130<6,"Poor")} -> Poor
A131: 1/14/2024 | B131: Brooklyn | C131: Normal | D131: Female | E131: Sports & Travel | F131: 34.81 | G131: 1 | H131: Credit card | I131: 7 | J131: =F131*G131 -> 34.81 | K131: =J131*5% -> 1.7405 | L131: {=_xlfn.IFS(I131>=9,"Good",I131>=6,"Average",I131<6,"Poor")} -> Average
... A353: 1/31/2024 | B353: Manhattan | C353: Member | D353: Male | E353: Electronics | F353: 66.35 | G353: 1 | H353: Credit card | I353: 9.7 | J353: =F353*G353 -> 66.35 | K353: =J353*5% -> 3.3175 | L353: {=_xlfn.IFS(I353>=9,"Good",I353>=6,"Average",I353<6,"Poor")} -> Good
A354: 45293 | B354: Queens | C354: Member | D354: Female | E354: Food & Beverages | F354: 87.48 | G354: 6 | H354: Ewallet | I354: 5.1 | J354: =F354*G354 -> 524.88 | K354: =J354*5% -> 26.244 | L354: {=_xlfn.IFS(I354>=9,"Good",I354>=6,"Average",I354<6,"Poor")} -> Poor
A355: 45293 | B355: Manhattan | C355: Member | D355: Female | E355: Food & Beverages | F355: 14.23 | G355: 5 | H355: Credit card | I355: 4.4 | J355: =F355*G355 -> 71.15 | K355: =J355*5% -> 3.5575 | L355: {=_xlfn.IFS(I355>=9,"Good",I355>=6,"Average",I355<6,"Poor")} -> Poor
A356: 45293 | B356: Manhattan | C356: Member | D356: Male | E356: Sports & Travel | F356: 69.52 | G356: 7 | H356: Credit card | I356: 8.5 | J356: =F356*G356 -> 486.64 | K356: =J356*5% -> 24.332 | L356: {=_xlfn.IFS(I356>=9,"Good",I356>=6,"Average",I356<6,"Poor")} -> Average
A357: 45293 | B357: Queens | C357: Normal | D357: Female | E357: Electronics | F357: 23.07 | G357: 9 | H357: Cash | I357: 4.9 | J357: =F357*G357 -> 207.63 | K357: =J357*5% -> 10.3815 | L357: {=_xlfn.IFS(I357>=9,"Good",I357>=6,"Average",I357<6,"Poor")} -> Poor
A358: 45293 | B358: Queens | C358: Member | D358: Female | E358: Home & Lifestyle | F358: 80.79 | G358: 9 | H358: Credit card | I358: 9.5 | J358: =F358*G358 -> 727.11 | K358: =J358*5% -> 36.3555 | L358: {=_xlfn.IFS(I358>=9,"Good",I358>=6,"Average",I358<6,"Poor")} -> Good
A359: 45293 | B359: Manhattan | C359: Member | D359: Female | E359: Health & Beauty | F359: 77.68 | G359: 4 | H359: Cash | I359: 8.4 | J359: =F359*G359 -> 310.72 | K359: =J359*5% -> 15.536 | L359: {=_xlfn.IFS(I359>=9,"Good",I359>=6,"Average",I359<6,"Poor")} -> Average
A360: 45324 | B360: Brooklyn | C360: Member | D360: Female | E360: Electronics | F360: 26.26 | G360: 7 | H360: Cash | I360: 9.9 | J360: =F360*G360 -> 183.82 | K360: =J360*5% -> 9.191 | L360: {=_xlfn.IFS(I360>=9,"Good",I360>=6,"Average",I360<6,"Poor")} -> Good
A361: 45324 | B361: Manhattan | C361: Member | D361: Male | E361: Fashion & Accs | F361: 43.13 | G361: 10 | H361: Credit card | I361: 5.5 | J361: =F361*G361 -> 431.3 | K361: =J361*5% -> 21.565 | L361: {=_xlfn.IFS(I361>=9,"Good",I361>=6,"Average",I361<6,"Poor")} -> Poor
A362: 45324 | B362: Brooklyn | C362: Normal | D362: Female | E362: Fashion & Accs | F362: 25.56 | G362: 7 | H362: Cash | I362: 7.1 | J362: =F362*G362 -> 178.92 | K362: =J362*5% -> 8.946 | L362: {=_xlfn.IFS(I362>=9,"Good",I362>=6,"Average",I362<6,"Poor")} -> Average
A363: 45324 | B363: Queens | C363: Member | D363: Female | E363: Food & Beverages | F363: 38.42 | G363: 1 | H363: Cash | I363: 8.6 | J363: =F363*G363 -> 38.42 | K363: =J363*5% -> 1.921 | L363: {=_xlfn.IFS(I363>=9,"Good",I363>=6,"Average",I363<6,"Poor")} -> Average
...

Sheet Clean Data
A1: Date | B1: Branch | C1: Customer type | D1: Gender | E1: Product line | F1: Unit price | G1: Quantity | H1: Payment | I1: Rating | J1: Total sales | K1: Tax amount | L1: Rating Category
A2: 45292 | B2: Brooklyn | C2: Member | D2: Female | E2: Food & Beverages | F2: 84.63 | G2: 10 | H2: Credit card | I2: 9 | J2: 846.3 | K2: 42.315 | L2: Good
A3: 45292 | B3: Queens | C3: Normal | D3: Female | E3: Electronics | F3: 63.22 | G3: 2 | H3: Cash | I3: 8.5 | J3: 126.44 | K3: 6.322 | L3: Good | N3: =AVERAGE(Table2_1[Rating]) -> 6.8840293
A4: 45292 | B4: Brooklyn | C4: Normal | D4: Female | E4: Electronics | F4: 74.71 | G4: 6 | H4: Cash | I4: 6.7 | J4: 448.26 | K4: 22.413 | L4: Average
A5: 45292 | B5: Queens | C5: Member | D5: Female | E5: Sports & Travel | F5: 36.98 | G5: 10 | H5: Credit card | I5: 7 | J5: 369.8 | K5: 18.49 | L5: Average
A6: 45292 | B6: Manhattan | C6: Member | D6: Female | E6: Sports & Travel | F6: 27.04 | G6: 4 | H6: Ewallet | I6: 6.9 | J6: 108.16 | K6: 5.408 | L6: Average
A7: 45292 | B7: Manhattan | C7: Normal | D7: Female | E7: Fashion & Accs | F7: 65.74 | G7: 9 | H7: Cash | I7: 7.7 | J7: 591.66 | K7: 29.583 | L7: Average
A8: 45292 | B8: Manhattan | C8: Member | D8: Male | E8: Home & Lifestyle | F8: 47.59 | G8: 8 | H8: Cash | I8: 5.7 | J8: 380.72 | K8: 19.036 | L8: Poor
A9: 45292 | B9: Manhattan | C9: Normal | D9: Male | E9: Sports & Travel | F9: 72.61 | G9: 6 | H9: Credit card | I9: 6.9 | J9: 435.66 | K9: 21.783 | L9: Average
A10: 45292 | B10: Queens | C10: Normal | D10: Male | E10: Health & Beauty | F10: 62.87 | G10: 2 | H10: Cash | I10: 5 | J10: 125.74 | K10: 6.287 | L10: Poor
A11: 45292 | B11: Brooklyn | C11: Normal | D11: Male | E11: Food & Beverages | F11: 21.12 | G11: 8 | H11: Cash | I11: 6.3 | J11: 168.96 | K11: 8.448 | L11: Average
A12: 45292 | B12: Queens | C12: Member | D12: Female | E12: Sports & Travel | F12: 29.22 | G12: 6 | H12: Ewallet | I12: 5 | J12: 175.32 | K12: 8.766 | L12: Poor
A13: 45292 | B13: Manhattan | C13: Member | D13: Female | E13: Electronics | F13: 74.22 | G13: 10 | H13: Credit card | I13: 4.3 | J13: 742.2 | K13: 37.11 | L13: Poor
A14: 45323 | B14: Manhattan | C14: Normal | D14: Male | E14: Sports & Travel | F14: 42.47 | G14: 1 | H14: Cash | I14: 5.7 | J14: 42.47 | K14: 2.1235 | L14: Poor
A15: 45323 | B15: Brooklyn | C15: Member | D15: Male | E15: Fashion & Accs | F15: 40.61 | G15: 9 | H15: Cash | I15: 7 | J15: 365.49 | K15: 18.2745 | L15: Average
... A119: 45627 | B119: Brooklyn | C119: Normal | D119: Female | E119: Home & Lifestyle | F119: 51.07 | G119: 7 | H119: Cash | I119: 7 | J119: 357.49 | K119: 17.8745 | L119: Average
B120: Brooklyn | C120: Member | D120: Male | E120: Sports & Travel | F120: 72.6 | G120: 6 | H120: Cash | I120: 6.9 | J120: 435.6 | K120: 21.78 | L120: Average
B121: Manhattan | C121: Member | D121: Male | E121: Home & Lifestyle | F121: 81.01 | G121: 3 | H121: Credit card | I121: 9.3 | J121: 243.03 | K121: 12.1515 | L121: Good
B122: Queens | C122: Member | D122: Female | E122: Fashion & Accs | F122: 74.29 | G122: 1 | H122: Cash | I122: 5 | J122: 74.29 | K122: 3.7145 | L122: Poor
B123: Manhattan | C123: Normal | D123: Female | E123: Electronics | F123: 23.46 | G123: 6 | H123: Ewallet | I123: 6.4 | J123: 140.76 | K123: 7.038 | L123: Average
B124: Manhattan | C124: Member | D124: Female | E124: Health & Beauty | F124: 39.62 | G124: 9 | H124: Credit card | I124: 6.8 | J124: 356.58 | K124: 17.829 | L124: Average
B125: Queens | C125: Member | D125: Female | E125: Food & Beverages | F125: 21.04 | G125: 4 | H125: Cash | I125: 7.6 | J125: 84.16 | K125: 4.208 | L125: Average
B126: Brooklyn | C126: Member | D126: Male | E126: Fashion & Accs | F126: 59.86 | G126: 2 | H126: Ewallet | I126: 6.7 | J126: 119.72 | K126: 5.986 | L126: Average
B127: Brooklyn | C127: Normal | D127: Male | E127: Food & Beverages | F127: 72.39 | G127: 2 | H127: Credit card | I127: 8.1 | J127: 144.78 | K127: 7.239 | L127: Good
B128: Manhattan | C128: Normal | D128: Male | E128: Sports & Travel | F128: 45.58 | G128: 7 | H128: Cash | I128: 5 | J128: 319.06 | K128: 15.953 | L128: Poor
B129: Queens | C129: Normal | D129: Female | E129: Electronics | F129: 41.65 | G129: 10 | H129: Credit card | I129: 5.4 | J129: 416.5 | K129: 20.825 | L129: Poor
B130: Queens | C130: Member | D130: Male | E130: Health & Beauty | F130: 60.47 | G130: 3 | H130: Credit card | I130: 5.6 | J130: 181.41 | K130: 9.0705 | L130: Poor
B131: Brooklyn | C131: Normal | D131: Female | E131: Sports & Travel | F131: 34.81 | G131: 1 | H131: Credit card | I131: 7 | J131: 34.81 | K131: 1.7405 | L131: Average
... B353: Manhattan | C353: Member | D353: Male | E353: Electronics | F353: 66.35 | G353: 1 | H353: Credit card | I353: 9.7 | J353: 66.35 | K353: 3.3175 | L353: Good
A354: 45293 | B354: Queens | C354: Member | D354: Female | E354: Food & Beverages | F354: 87.48 | G354: 6 | H354: Ewallet | I354: 5.1 | J354: 524.88 | K354: 26.244 | L354: Poor
A355: 45293 | B355: Manhattan | C355: Member | D355: Female | E355: Food & Beverages | F355: 14.23 | G355: 5 | H355: Credit card | I355: 4.4 | J355: 71.15 | K355: 3.5575 | L355: Poor
A356: 45293 | B356: Manhattan | C356: Member | D356: Male | E356: Sports & Travel | F356: 69.52 | G356: 7 | H356: Credit card | I356: 8.5 | J356: 486.64 | K356: 24.332 | L356: Good
A357: 45293 | B357: Queens | C357: Normal | D357: Female | E357: Electronics | F357: 23.07 | G357: 9 | H357: Cash | I357: 4.9 | J357: 207.63 | K357: 10.3815 | L357: Poor
A358: 45293 | B358: Queens | C358: Member | D358: Female | E358: Home & Lifestyle | F358: 80.79 | G358: 9 | H358: Credit card | I358: 9.5 | J358: 727.11 | K358: 36.3555 | L358: Good
A359: 45293 | B359: Manhattan | C359: Member | D359: Female | E359: Health & Beauty | F359: 77.68 | G359: 4 | H359: Cash | I359: 8.4 | J359: 310.72 | K359: 15.536 | L359: Good
A360: 45324 | B360: Brooklyn | C360: Member | D360: Female | E360: Electronics | F360: 26.26 | G360: 7 | H360: Cash | I360: 9.9 | J360: 183.82 | K360: 9.191 | L360: Good
A361: 45324 | B361: Manhattan | C361: Member | D361: Male | E361: Fashion & Accs | F361: 43.13 | G361: 10 | H361: Credit card | I361: 5.5 | J361: 431.3 | K361: 21.565 | L361: Poor
A362: 45324 | B362: Brooklyn | C362: Normal | D362: Female | E362: Fashion & Accs | F362: 25.56 | G362: 7 | H362: Cash | I362: 7.1 | J362: 178.92 | K362: 8.946 | L362: Average
A363: 45324 | B363: Queens | C363: Member | D363: Female | E363: Food & Beverages | F363: 38.42 | G363: 1 | H363: Cash | I363: 8.6 | J363: 38.42 | K363: 1.921 | L363: Good
A364: 45324 | B364: Queens | C364: Normal | D364: Male | E364: Food & Beverages | F364: 65.97 | G364: 8 | H364: Cash | I364: 8.4 | J364: 527.76 | K364: 26.388 | L364: Good
...

Sheet Data Analysis
A1: SUPERMARKET SALES DATA ANALYSIS
A3: 1. Which branch generates the highest total sales? | C3: BRANCH | D3: Total Sales | E3: No.of Sales | F3: Average Sales
C4: {=_xlfn.UNIQUE(Table2_1[Branch])} -> Brooklyn | D4: =SUMIF(Table2_1[Branch],$C4,Table2_1[Total sales]) -> 319705.48 | E4: =COUNTIF(Table2_1[Branch],$C4) -> 1793 | F4: =AVERAGEIF(Table2_1[Branch],$C4,Table2_1[Total sales]) -> 178.30757
C5: Queens | D5: =SUMIF(Table2_1[Branch],$C5,Table2_1[Total sales]) -> 312842.82 | E5: =COUNTIF(Table2_1[Branch],$C5) -> 1555 | F5: =AVERAGEIF(Table2_1[Branch],$C5,Table2_1[Total sales]) -> 201.18509
C6: Manhattan | D6: =SUMIF(Table2_1[Branch],$C6,Table2_1[Total sales]) -> 309996.55 | E6: =COUNTIF(Table2_1[Branch],$C6) -> 1705 | F6: =AVERAGEIF(Table2_1[Branch],$C6,Table2_1[Total sales]) -> 181.81616
A8: 2.Which product line generates the highest sales and sells the most quantity? | C8: Products | D8: Total Sales | E8: Total Quantity
C9: {=_xlfn.UNIQUE(Table2_1[Product line])} -> Food & Beverages | D9: =SUMIF(Table2_1[Product line],$C9,Table2_1[Total sales]) -> 151357.73 | E9: =SUMIF(Table2_1[Product line],$C9,Table2_1[Quantity]) -> 7309
C10: Electronics | D10: =SUMIF(Table2_1[Product line],$C10,Table2_1[Total sales]) -> 159259.1 | E10: =SUMIF(Table2_1[Product line],$C10,Table2_1[Quantity]) -> 2325
C11: Sports & Travel | D11: =SUMIF(Table2_1[Product line],$C11,Table2_1[Total sales]) -> 164252.94 | E11: =SUMIF(Table2_1[Product line],$C11,Table2_1[Quantity]) -> 2697
C12: Fashion & Accs | D12: =SUMIF(Table2_1[Product line],$C12,Table2_1[Total sales]) -> 101843.91 | E12: =SUMIF(Table2_1[Product line],$C12,Table2_1[Quantity]) -> 3123
C13: Home & Lifestyle | D13: =SUMIF(Table2_1[Product line],$C13,Table2_1[Total sales]) -> 197260.56 | E13: =SUMIF(Table2_1[Product line],$C13,Table2_1[Quantity]) -> 3461
C14: Health & Beauty | D14: =SUMIF(Table2_1[Product line],$C14,Table2_1[Total sales]) -> 168570.61 | E14: =SUMIF(Table2_1[Product line],$C14,Table2_1[Quantity]) -> 4296
A16: 3. How do Member and Normal customers differ in their spending? | C16: Customer type | D16: Total Sales | E16: No.of Sales | F16: Average Sales | G16: Total Quantity
C17: Member | D17: =SUMIF(Table2_1[Customer type],$C17,Table2_1[Total sales]) -> 436368.17 | E17: =COUNTIF(Table2_1[Customer type],$C17) -> 2085 | F17: =AVERAGEIF(Table2_1[Customer type],$C17,Table2_1[Total sales]) -> 209.28929 | G17: =SUMIF(Table2_1[Customer type],$C17,Table2_1[Quantity]) -> 10089
C18: Normal | D18: =SUMIF(Table2_1[Customer type],$C18,Table2_1[Total sales]) -> 506176.68 | E18: =COUNTIF(Table2_1[Customer type],$C18) -> 2968 | F18: =AVERAGEIF(Table2_1[Customer type],$C18,Table2_1[Total sales]) -> 170.5447 | G18: =SUMIF(Table2_1[Customer type],$C18,Table2_1[Quantity]) -> 13122
A20: 4. Which payment method is most commonly used and generates the highest sales? | C20: Payment Method | D20: Total Sales | E20: Payment count
C21: {=_xlfn.UNIQUE(Table2_1[Payment])} -> Credit card | D21: =SUMIF(Table2_1[Payment],'Data Analysis'!$C21,Table2_1[Total sales]) -> 311230.89 | E21: =COUNTIF(Table2_1[Payment],'Data Analysis'!$C21) -> 1594
C22: Cash | D22: =SUMIF(Table2_1[Payment],'Data Analysis'!$C22,Table2_1[Total sales]) -> 304622.65 | E22: =COUNTIF(Table2_1[Payment],'Data Analysis'!$C22) -> 1674
C23: Ewallet | D23: =SUMIF(Table2_1[Payment],'Data Analysis'!$C23,Table2_1[Total sales]) -> 326691.31 | E23: =COUNTIF(Table2_1[Payment],'Data Analysis'!$C23) -> 1785
A25: 5. Is customer rating related to sales performance? | C25: Rating Category | D25: No.of ratings | E25: Total Sales | F25: Average Sales | G25: Average Rating
C26: {=_xlfn.UNIQUE(Table2_1[Rating Category])} -> Good | D26: =COUNTIF(Table2_1[Rating Category],'Data Analysis'!$C26) -> 1529 | E26: =SUMIF(Table2_1[Rating Category],'Data Analysis'!$C26,Table2_1[Total sales]) -> 286422.23 | F26: =AVERAGEIF(Table2_1[Rating Category],'Data Analysis'!$C26,Table2_1[Total sales]) -> 187.32651 | G26: =AVERAGEIF(Table2_1[Rating Category],'Data Analysis'!$C26,Table2_1[Rating]) -> 8.8301504
C27: Average | D27: =COUNTIF(Table2_1[Rating Category],'Data Analysis'!$C27) -> 2043 | E27: =SUMIF(Table2_1[Rating Category],'Data Analysis'!$C27,Table2_1[Total sales]) -> 330894.46 | F27: =AVERAGEIF(Table2_1[Rating Category],'Data Analysis'!$C27,Table2_1[Total sales]) -> 161.96498 | G27: =AVERAGEIF(Table2_1[Rating Category],'Data Analysis'!$C27,Table2_1[Rating]) -> 6.9919236
C28: Poor | D28: =COUNTIF(Table2_1[Rating Category],'Data Analysis'!$C28) -> 1481 | E28: =SUMIF(Table2_1[Rating Category],'Data Analysis'!$C28,Table2_1[Total sales]) -> 325228.16 | F28: =AVERAGEIF(Table2_1[Rating Category],'Data Analysis'!$C28,Table2_1[Total sales]) -> 219.60038 | G28: =AVERAGEIF(Table2_1[Rating Category],'Data Analysis'!$C28,Table2_1[Rating]) -> 4.7259959

Sheet Questions
A1: SUPERMARKET SALES ANALYSIS
A2: No. | B2: Business Questions
A3: 1 | B3: Which branch generates the highest total sales?
A4: 2 | B4: Which product line generates the highest sales and sells the most quantity?
A5: 3 | B5: How do Member and Normal customers differ in their spending?
A6: 4 | B6: Which payment method is most commonly used and generates the highest sales?

Sheet DASHBOARD

Sheet INSIGHTS
E4: INSIGHTS | F4: RECOMMENDATIONS
E5: Brooklyn has the highest total sales at 319,705.48. | F5: Study Brooklyn's successful sales practices and apply them to other branches.
E6: Home & Lifestyle has the highest sales, while Food & Beverages has the highest quantity sold. | F6: Maintain Food & Beverages stock and promote Home & Lifestyle products.
E7: Members spend more per sale (209.29), while Normal customers generate higher total sales. | F7: Encourage Normal customers to join the membership program.
E8: Ewallet is the most used payment method and has the highest sales at 326,691.31. | F8: Continue supporting Ewallet and ensure reliable digital payments.
E9: Poor-rated sales have the highest average value (219.60), so higher ratings do not mean higher sales. | F9: Investigate reasons for poor ratings, especially on high-value purchases.

Sheet Changelog
G7: CHANGE MADE | H7: REASON
G8: Removed duplicate records | H8: To avoid duplicate sales data
G9: Corrected inconsistent text values | H9: To maintain consistent categories.
G10: Standardized column names | H10: To make the dataset clear and easy to analyze
G11: Checked and corrected data types | H11: To ensure values are suitable for analysis
G12: Added Tax Amount column | H12: To calculate the tax amount for each sale.
G13: Added Total Sales column | H13: To calculate the final sales amount including tax.
G14: Created Rating Category | H14: To group customer ratings into Good, Average, and Poor.
G15: Created PivotTables | H15: To summarize data and validate the analysis.
G16: Added formulas for business questions | H16: To provide data-driven answers.
G17: Added charts, slicers and KPI cards | H17: To create an interactive dashboard.

Sheet spark
A3: Row Labels | B3: Sum of Total sales
A4: <01-01-2024 | B4: 532465.92
A5: Jan | B5: 36420.88
A6: Feb | B6: 38399.9
A7: Mar | B7: 35443.64
A8: Apr | B8: 35878.12
A9: May | B9: 40137.64
A10: Jun | B10: 29753.03
A11: Jul | B11: 28843.67
A12: Aug | B12: 34056.65
A13: Sep | B13: 34642.57
A14: Oct | B14: 29701.94
A15: Nov | B15: 31112.91
... A17: Grand Total | B17: 942544.85

Sheet KPI
A3: Row Labels | B3: Sum of Total sales | C3: Sum of Quantity
A4: Electronics | B4: 159259.1 | C4: 2325
A5: Fashion & Accs | B5: 101843.91 | C5: 3123
A6: Food & Beverages | B6: 151357.73 | C6: 7309
A7: Health & Beauty | B7: 168570.61 | C7: 4296
A8: Home & Lifestyle | B8: 197260.56 | C8: 3461
A9: Sports & Travel | B9: 164252.94 | C9: 2697
A10: Grand Total | B10: 942544.85 | C10: 23211

Sheet Pivot_Branch
A3: Branch | B3: Sum of Total sales
A4: Brooklyn | B4: 319705.48
A5: Manhattan | B5: 309996.55
A6: Queens | B6: 312842.82
A7: Grand Total | B7: 942544.85

Sheet Pivot_Product
A3: Product | B3: Sum of Total sales | C3: Sum of Quantity
A4: Electronics | B4: 159259.1 | C4: 2325
A5: Fashion & Accs | B5: 101843.91 | C5: 3123
A6: Food & Beverages | B6: 151357.73 | C6: 7309
A7: Health & Beauty | B7: 168570.61 | C7: 4296
A8: Home & Lifestyle | B8: 197260.56 | C8: 3461
A9: Sports & Travel | B9: 164252.94 | C9: 2697
A10: Grand Total | B10: 942544.85 | C10: 23211

Sheet Pivot_customer
A3: Customer | B3: Sum of Total sales
A4: Member | B4: 436368.17
A5: Normal | B5: 506176.68
A6: Grand Total | B6: 942544.85

Sheet Pivot_Payment
A3: Payment method | B3: Count of Payment
A4: Cash | B4: 1674
A5: Credit card | B5: 1594
A6: Ewallet | B6: 1785
A7: Grand Total | B7: 5053

Sheet Pivot_Rating
A3: Rating
A4: Good
A5: Grand Total
